Workbook

Sheet Painel Manutenção
A1: Painel de manutenção periódica
A4: Total projetos | D4: Com Manuntenção Prev | G4: Com Contrato Ativo | J4: Contratos de Man Prev Expirados | M4: Contratos que acabam nos proximos 6 meses
A5: =COUNTA('Project Overview'!B:B)-1 -> 264 | D5: =COUNTIF('Project Overview'!N:N,"yes") -> 88 | G5: =COUNTIF('Project Overview'!Y:Y,"yes") -> 80 | J5: =COUNTIFS('Project Overview'!Y:Y,"no",'Project Overview'!N:N,"yes") -> 8 | M5: =COUNTIFS('Project Overview'!W:W,">="&TODAY(),'Project Overview'!W:W,"<="&EDATE(TODAY(),6)) -> 4
A9: Estado dos projetos | H9: ="Taxa de retenção: " & TEXT(I12/I13,"0%") -> Taxa de retenção: 90%
A10: Tipo de Contrato | B10: Contagem | H10: Estado de Contrato | I10: Contagem
A11: =Painel_Apoio!A5 -> EPC | B11: =Painel_Apoio!B5 -> 22 | H11: =Painel_Apoio!D5 -> no | I11: =Painel_Apoio!E5 -> 9
A12: =Painel_Apoio!A6 -> ESCO | B12: =Painel_Apoio!B6 -> 67 | H12: =Painel_Apoio!D6 -> yes | I12: =Painel_Apoio!E6 -> 80
A13: =Painel_Apoio!A7 -> Grand Total | B13: =Painel_Apoio!B7 -> 89 | H13: =Painel_Apoio!D7 -> Grand Total | I13: =Painel_Apoio!E7 -> 89
A26: Localizações com mais projetos | I26: Finalização de Contratos
A27: Principais Localizações | B27: Contagem | I27: Ano Conclusão | J27: Contagem
A28: =Painel_Apoio!J5 -> Lisboa | B28: =Painel_Apoio!K5 -> 8 | I28: =Painel_Apoio!M5 -> 2026 | J28: =Painel_Apoio!N5 -> 5
A29: =Painel_Apoio!J6 -> Leiria | B29: =Painel_Apoio!K6 -> 8 | I29: =Painel_Apoio!M6 -> 2027 | J29: =Painel_Apoio!N6 -> 8
A30: =Painel_Apoio!J7 -> Santarém | B30: =Painel_Apoio!K7 -> 7 | I30: =Painel_Apoio!M7 -> 2028 | J30: =Painel_Apoio!N7 -> 5
A31: =Painel_Apoio!J8 -> Sintra | B31: =Painel_Apoio!K8 -> 6 | I31: =Painel_Apoio!M8 -> 2029 | J31: =Painel_Apoio!N8 -> 3
A32: =Painel_Apoio!J9 -> Porto | B32: =Painel_Apoio!K9 -> 4 | I32: =Painel_Apoio!M9 -> 2032 | J32: =Painel_Apoio!N9 -> 3
A33: =Painel_Apoio!J10 -> Castelo Branco | B33: =Painel_Apoio!K10 -> 4 | I33: =Painel_Apoio!M10 -> 2033 | J33: =Painel_Apoio!N10 -> 7
A34: =Painel_Apoio!J11 -> Setúbal | B34: =Painel_Apoio!K11 -> 4 | I34: =Painel_Apoio!M11 -> 2034 | J34: =Painel_Apoio!N11 -> 3
A35: =Painel_Apoio!J12 -> Aveiro | B35: =Painel_Apoio!K12 -> 3 | I35: =Painel_Apoio!M12 -> 2035 | J35: =Painel_Apoio!N12 -> 7
A36: =Painel_Apoio!J13 -> Badajoz | B36: =Painel_Apoio!K13 -> 3 | I36: =Painel_Apoio!M13 -> 2036 | J36: =Painel_Apoio!N13 -> 10
A37: =Painel_Apoio!J14 -> São João da Madeira | B37: =Painel_Apoio!K14 -> 2 | I37: =Painel_Apoio!M14 -> 2037 | J37: =Painel_Apoio!N14 -> 5
I38: =Painel_Apoio!M15 -> 2038 | J38: =Painel_Apoio!N15 -> 16
I39: =Painel_Apoio!M16 -> 2039 | J39: =Painel_Apoio!N16 -> 5
I40: =Painel_Apoio!M17 -> 2041 | J40: =Painel_Apoio!N17 -> 2
I41: =Painel_Apoio!M18 -> 2043 | J41: =Painel_Apoio!N18 -> 1
A43: Alertas rápidos

Sheet Project Overview
A1: N° | B1: Project | C1: Company Name | D1: Nif | E1: Address | F1: Location | G1: Nº Panels | H1: Kwp | I1: Type of Contract | J1: Sell To | K1: Duration | L1: Duration Month2 | M1: Start Contract | N1: Maintenance | O1: Type of Coverage | P1: Access | Q1: Maintenance comment | R1: Status Detail | S1: Nome da Pessoa | T1: Cargo | U1: Email | V1: Telefone | W1: End Contract | X1: Year of End Contract | Y1: Active Contract | Z1: Notes | AA1: €€ | AB1: Tipo
A2: 1 | B2: A Colmeia do Minho | C2: A Colmeia do Minho, S.A., | D2: 500001022 | E2: Rua Jose Gregorio Almeida 14, Quinta da Cucena, 2840-582 Aldeia de Paio Pires Seixal | F2: Castelo Branco | G2: 220 | H2: 61.6 | I2: ESCO | J2: Solcorelios | K2: 7 | L2: =Table1[[#This Row],[Duration]]*12 -> 84 | M2: 43724 | N2: =IF(AND(Table1[[#This Row],[ Type of Contract]]="ESCO",Table1[[#This Row],[Status Detail]]="ACTIVE"),"yes","no") -> yes | O2: Sandwich | P2: Cobertura | R2: ACTIVE | S2: António Diogo Jacinto | T2: Presidente do Conselho de Administragdo | U2: pjacinto@acolmeiadominho.com.pt / geral@acolmeiadominho.com .pt | V2: 212279020 | W2: =IF(Table1[[#This Row],[Maintenance]]="yes",IF(OR(Table1[[#This Row],[Start Contract]]="",Table1[[#This Row],[Duration Month2]]=""),"",EDATE(Table1[[#This Row],[Start Contract]],Table1[[#This Row],[Duration Month2]])),"-") -> 46281 | X2: =IF(OR((W2=""),(W2="-")),"",YEAR(Table1[[#This Row],[End Contract]])) -> 2026 | Y2: =IF(Table1[[#This Row],[Maintenance]]="yes",IF(Table1[[#This Row],[End Contract]]="","no",IF(TODAY()<=Table1[[#This Row],[End Contract]],"yes","no")),"no") -> yes | AA2: - | AB2: Tarifa
A3: 2 | B3: Florineve | C3: Florineve - Produção e Comércio de Flores de Corte | D3: 510912974 | E3: Estr. do Seixalinho, 2870-491 Montijo | F3: Setúbal | G3: 272 | H3: 89.8 | I3: ESCO | J3: Solcorelios | K3: 15 | L3: =Table1[[#This Row],[Duration]]*12 -> 180 | M3: 43803 | N3: =IF(AND(Table1[[#This Row],[ Type of Contract]]="ESCO",Table1[[#This Row],[Status Detail]]="ACTIVE"),"yes","no") -> yes | O3: Sandwich | P3: Escada | R3: ACTIVE | S3: Victor Manuel de Amaral Araújo Abreu | T3: Sócio-gerente | U3: victor.araujo@florineve.pt / geral@florineve.pt | V3: 917275304 | W3: =IF(Table1[[#This Row],[Maintenance]]="yes",IF(OR(Table1[[#This Row],[Start Contract]]="",Table1[[#This Row],[Duration Month2]]=""),"",EDATE(Table1[[#This Row],[Start Contract]],Table1[[#This Row],[Duration Month2]])),"-") -> 49282 | X3: =IF(OR((W3=""),(W3="-")),"",YEAR(Table1[[#This Row],[End Contract]])) -> 2034 | Y3: =IF(Table1[[#This Row],[Maintenance]]="yes",IF(Table1[[#This Row],[End Contract]]="","no",IF(TODAY()<=Table1[[#This Row],[End Contract]],"yes","no")),"no") -> yes | AA3: - | AB3: Tarifa
A4: 3 | B4: Dialogos do Bosque | C4: Diálogos do Bosque, Unipessoal, LDA | D4: 510731570 | E4: Herdade dos Catos - Gralheira CCI 1304, 7050-636 Cortiçadas de Lavre | F4: Évora | G4: 90 | H4: 29.7 | I4: ESCO | J4: Solcorelios | K4: 15 | L4: =Table1[[#This Row],[Duration]]*12 -> 180 | M4: 43831 | N4: =IF(AND(Table1[[#This Row],[ Type of Contract]]="ESCO",Table1[[#This Row],[Status Detail]]="ACTIVE"),"yes","no") -> yes | O4: Sandwich | P4: Escada | R4: ACTIVE | T4: Gerente | U4: nuno.pires@dialogosdobosque.pt / info@dialogosdobosque.pt | V4: 938654762 / 917285177 | W4: =IF(Table1[[#This Row],[Maintenance]]="yes",IF(OR(Table1[[#This Row],[Start Contract]]="",Table1[[#This Row],[Duration Month2]]=""),"",EDATE(Table1[[#This Row],[Start Contract]],Table1[[#This Row],[Duration Month2]])),"-") -> 49310 | X4: =IF(OR((W4=""),(W4="-")),"",YEAR(Table1[[#This Row],[End Contract]])) -> 2035 | Y4: =IF(Table1[[#This Row],[Maintenance]]="yes",IF(Table1[[#This Row],[End Contract]]="","no",IF(TODAY()<=Table1[[#This Row],[End Contract]],"yes","no")),"no") -> yes | AA4: - | AB4: Tarifa
A5: 4 | B5: Presuntos Lourenço 2 | C5: A. Pires Lourenço & Filhos S.A | D5: 502265906 | E5: Rua do Outeiro 154, Cebolais de Cima, Castelo Branco, Portugal | F5: Castelo Branco | G5: 684 | H5: 307.8 | I5: EPC | J5: Cliente | K5: 2 | L5: =Table1[[#This Row],[Duration]]*12 -> 24 | M5: 45474 | N5: yes | O5: Sandwich | P5: Escada Vertical | Q5: To discuss with the client | R5: ACTIVE | S5: Vítor Manuel Rodrigues Lourenço | T5: Gerente | U5: apireslourenco@apireslourenco.pt / mario@apireslourenco.pt / victor@apireslourenco.pt | V5: 962546961 | W5: =IF(Table1[[#This Row],[Maintenance]]="yes",IF(OR(Table1[[#This Row],[Start Contract]]="",Table1[[#This Row],[Duration Month2]]=""),"",EDATE(Table1[[#This Row],[Start Contract]],Table1[[#This Row],[Duration Month2]])),"-") -> 46204 | X5: =IF(OR((W5=""),(W5="-")),"",YEAR(Table1[[#This Row],[End Contract]])) -> 2026 | Y5: =IF(Table1[[#This Row],[Maintenance]]="yes",IF(Table1[[#This Row],[End Contract]]="","no",IF(TODAY()<=Table1[[#This Row],[End Contract]],"yes","no")),"no") -> yes | Z5: Missing contract duration (EPC) | AA5: 1750 | AB5: O&M
A6: 4 | B6: Pires Lourenço 1 | C6: A. Pires Lourenço & Filhos S.A | D6: 502265906 | E6: Empresarial Rua I - Lote 129, Apartado 1142 6001-901 Castelo Branco | F6: Castelo Branco | G6: 648 | H6: 243 | I6: ESCO | J6: Solcorelios | K6: 8 | L6: =Table1[[#This Row],[Duration]]*12 -> 96 | M6: 44013 | N6: =IF(AND(Table1[[#This Row],[ Type of Contract]]="ESCO",Table1[[#This Row],[Status Detail]]="ACTIVE"),"yes","no") -> yes | O6: Sandwich | P6: Cobertura | R6: ACTIVE | S6: Vítor Manuel Rodrigues Lourenço | T6: Gerente | U6: apireslourenco@apireslourenco.pt / mario@apireslourenco.pt / victor@apireslourenco.pt | V6: 272989489 | W6: =IF(Table1[[#This Row],[Maintenance]]="yes",IF(OR(Table1[[#This Row],[Start Contract]]="",Table1[[#This Row],[Duration Month2]]=""),"",EDATE(Table1[[#This Row],[Start Contract]],Table1[[#This Row],[Duration Month2]])),"-") -> 46935 | X6: =IF(OR((W6=""),(W6="-")),"",YEAR(Table1[[#This Row],[End Contract]])) -> 2028 | Y6: =IF(Table1[[#This Row],[Maintenance]]="yes",IF(Table1[[#This Row],[End Contract]]="","no",IF(TODAY()<=Table1[[#This Row],[End Contract]],"yes","no")),"no") -> yes | AA6: - | AB6: Tarifa
A7: 5 | B7: Usinage | C7: Usinage - Maquinação e Porta Moldes, Lda | D7: 505435748 | E7: Estrada Nacional 356, n.º 87, Maceirinha, 2405-026 Maceira LRA | F7: Leiria | G7: 360 | H7: 138.6 | I7: ESCO BUYOUT | J7: Solcorelios | K7: 15 | L7: =Table1[[#This Row],[Duration]]*12 -> 180 | M7: 44136 | N7: =IF(AND(Table1[[#This Row],[ Type of Contract]]="ESCO",Table1[[#This Row],[Status Detail]]="ACTIVE"),"yes","no") -> no | O7: Sandwich | P7: Escada | R7: ACTIVE | S7: Pedro Miguel da Silva Rodrigues | T7: Gerente | U7: comercial@usinage.pt / geral@usinage.pt | V7: 917569054 | W7: =IF(Table1[[#This Row],[Maintenance]]="yes",IF(OR(Table1[[#This Row],[Start Contract]]="",Table1[[#This Row],[Duration Month2]]=""),"",EDATE(Table1[[#This Row],[Start Contract]],Table1[[#This Row],[Duration Month2]])),"-") -> - | X7: =IF(OR((W7=""),(W7="-")),"",YEAR(Table1[[#This Row],[End Contract]])) | Y7: =IF(Table1[[#This Row],[Maintenance]]="yes",IF(Table1[[#This Row],[End Contract]]="","no",IF(TODAY()<=Table1[[#This Row],[End Contract]],"yes","no")),"no") -> no
A8: 6 | B8: Museu Caramulo | C8: Fundação Abel e João de Lacerda | D8: 500792640 | E8: Museu do Caramulo 3475-031 Caramulo | F8: Tondela | G8: 68 | H8: 26.18 | I8: ESCO | J8: Solcorelios | K8: =84/12 -> 7 | L8: =Table1[[#This Row],[Duration]]*12 -> 84 | M8: 44105 | N8: =IF(AND(Table1[[#This Row],[ Type of Contract]]="ESCO",Table1[[#This Row],[Status Detail]]="ACTIVE"),"yes","no") -> yes | O8: Telha | P8: Escada | R8: ACTIVE | S8: Tiago Patricio Lacerda pinto Basto Gouveia | T8: Vogal da Direção/Diretor Delegado | U8: tiago.gouveia@museu-caramulo.net / salvador.gouveia@museudocaramulo.pt | V8: 232861270 | W8: =IF(Table1[[#This Row],[Maintenance]]="yes",IF(OR(Table1[[#This Row],[Start Contract]]="",Table1[[#This Row],[Duration Month2]]=""),"",EDATE(Table1[[#This Row],[Start Contract]],Table1[[#This Row],[Duration Month2]])),"-") -> 46661 | X8: =IF(OR((W8=""),(W8="-")),"",YEAR(Table1[[#This Row],[End Contract]])) -> 2027 | Y8: =IF(Table1[[#This Row],[Maintenance]]="yes",IF(Table1[[#This Row],[End Contract]]="","no",IF(TODAY()<=Table1[[#This Row],[End Contract]],"yes","no")),"no") -> yes | AA8: - | AB8: Tarifa
A9: 7 | B9: Confrontar Sabores | C9: Confrontan Sabores, Lda | D9: 509891500 | E9: Zona Industrial de Albergaria-A-Velha, Arruamento H, Lote 4 3850-184 Albergaria-A-Velha | H9: 45 | I9: ESCO | J9: Solcorelios | K9: 15 | L9: =Table1[[#This Row],[Duration]]*12 -> 180 | N9: =IF(AND(Table1[[#This Row],[ Type of Contract]]="ESCO",Table1[[#This Row],[Status Detail]]="ACTIVE"),"yes","no") -> no | R9: CANCELLED | S9: António da Rocha Martins | T9: Gerente | W9: =IF(Table1[[#This Row],[Maintenance]]="yes",IF(OR(Table1[[#This Row],[Start Contract]]="",Table1[[#This Row],[Duration Month2]]=""),"",EDATE(Table1[[#This Row],[Start Contract]],Table1[[#This Row],[Duration Month2]])),"-") -> - | X9: =IF(OR((W9=""),(W9="-")),"",YEAR(Table1[[#This Row],[End Contract]])) | Y9: =IF(Table1[[#This Row],[Maintenance]]="yes",IF(Table1[[#This Row],[End Contract]]="","no",IF(TODAY()<=Table1[[#This Row],[End Contract]],"yes","no")),"no") -> no
A10: 8 | B10: Marmores da Granja | C10: Marmores da Granja Lda | D10: 501754679 | E10: Av. da Aviação Portuguesa 82 - Lameiras 2715-776 Terrugem Snt | F10: Sintra | G10: 360 | H10: 138.6 | I10: ESCO | J10: Solcorelios | K10: 15 | L10: =Table1[[#This Row],[Duration]]*12 -> 180 | M10: 44228 | N10: =IF(AND(Table1[[#This Row],[ Type of Contract]]="ESCO",Table1[[#This Row],[Status Detail]]="ACTIVE"),"yes","no") -> yes | O10: Sandwich | P10: Escada | R10: ACTIVE | S10: Eugénia Maria Nunes Marcelino Firmino / Américo Manuel Ventura Firmino | T10: Sócio-gerente | U10: eugenia@marmoresgranja.pt / granja@marmoresgranja.pt | V10: 968064212/966475439 | W10: =IF(Table1[[#This Row],[Maintenance]]="yes",IF(OR(Table1[[#This Row],[Start Contract]]="",Table1[[#This Row],[Duration Month2]]=""),"",EDATE(Table1[[#This Row],[Start Contract]],Table1[[#This Row],[Duration Month2]])),"-") -> 49706 | X10: =IF(OR((W10=""),(W10="-")),"",YEAR(Table1[[#This Row],[End Contract]])) -> 2036 | Y10: =IF(Table1[[#This Row],[Maintenance]]="yes",IF(Table1[[#This Row],[End Contract]]="","no",IF(TODAY()<=Table1[[#This Row],[End Contract]],"yes","no")),"no") -> yes | AA10: - | AB10: Tarifa
A11: 9 | B11: Lands Hause - Pataias | C11: Ah Pinhal do Rei, Lda | D11: 514968044 | E11: 2445-045 Pataias | F11: Leiria | G11: 68 | H11: 26.86 | I11: ESCO BUYOUT | J11: Solcorelios | K11: 8 | L11: =Table1[[#This Row],[Duration]]*12 -> 96 | M11: 44287 | N11: =IF(AND(Table1[[#This Row],[ Type of Contract]]="ESCO",Table1[[#This Row],[Status Detail]]="ACTIVE"),"yes","no") -> no | O11: Sandwich | P11: Escada | R11: ACTIVE | S11: Manuel Joaquim de Oliveira Brites | T11: Gerente | U11: mblello@hotmail.com | V11: 912378796 | W11: =IF(Table1[[#This Row],[Maintenance]]="yes",IF(OR(Table1[[#This Row],[Start Contract]]="",Table1[[#This Row],[Duration Month2]]=""),"",EDATE(Table1[[#This Row],[Start Contract]],Table1[[#This Row],[Duration Month2]])),"-") -> - | X11: =IF(OR((W11=""),(W11="-")),"",YEAR(Table1[[#This Row],[End Contract]])) | Y11: =IF(Table1[[#This Row],[Maintenance]]="yes",IF(Table1[[#This Row],[End Contract]]="","no",IF(TODAY()<=Table1[[#This Row],[End Contract]],"yes","no")),"no") -> no
A12: 10 | B12: Lusobatata | C12: Lusobatata- Produtos de lV Gama, LDA | D12: 503722170 | E12: Av, Sra. Da Lapa, N84, Barreiralva, 2640416 Mafra | F12: Mafra | G12: 158 | H12: 59.25 | I12: ESCO | J12: Solcorelios | K12: 7 | L12: =Table1[[#This Row],[Duration]]*12 -> 84 | M12: 44348 | N12: =IF(AND(Table1[[#This Row],[ Type of Contract]]="ESCO",Table1[[#This Row],[Status Detail]]="ACTIVE"),"yes","no") -> yes | O12: Sandwich | P12: Escada | R12: ACTIVE | S12: Feliciano Ricardo Fernando | T12: Gerente | U12: geral@lusobatata.com / filipe.ricardo@lusobatata.com | V12: 939017210 | W12: =IF(Table1[[#This Row],[Maintenance]]="yes",IF(OR(Table1[[#This Row],[Start Contract]]="",Table1[[#This Row],[Duration Month2]]=""),"",EDATE(Table1[[#This Row],[Start Contract]],Table1[[#This Row],[Duration Month2]])),"-") -> 46905 | X12: =IF(OR((W12=""),(W12="-")),"",YEAR(Table1[[#This Row],[End Contract]])) -> 2028 | Y12: =IF(Table1[[#This Row],[Maintenance]]="yes",IF(Table1[[#This Row],[End Contract]]="","no",IF(TODAY()<=Table1[[#This Row],[End Contract]],"yes","no")),"no") -> yes | AA12: - | AB12: Tarifa
A13: 11 | B13: Solidus | C13: Solidus Soluções Para Ferramentas e Moldes, Lda. | D13: 505030896 | E13: Avenida D. João V, Nº. 35, 1º., Dtº. 2610-087 Amadora | F13: Sintra | G13: 114 | H13: 45.03 | I13: ESCO | J13: Solcorelios | K13: 15 | L13: =Table1[[#This Row],[Duration]]*12 -> 180 | M13: 44287 | N13: =IF(AND(Table1[[#This Row],[ Type of Contract]]="ESCO",Table1[[#This Row],[Status Detail]]="ACTIVE"),"yes","no") -> yes | O13: Sandwich | P13: Escada | R13: ACTIVE | S13: Paulo Alexandre dos Santos Lourenço | T13: Gerente | U13: solidus@sapo.pt | V13: 912006543 | W13: =IF(Table1[[#This Row],[Maintenance]]="yes",IF(OR(Table1[[#This Row],[Start Contract]]="",Table1[[#This Row],[Duration Month2]]=""),"",EDATE(Table1[[#This Row],[Start Contract]],Table1[[#This Row],[Duration Month2]])),"-") -> 49766 | X13: =IF(OR((W13=""),(W13="-")),"",YEAR(Table1[[#This Row],[End Contract]])) -> 2036 | Y13: =IF(Table1[[#This Row],[Maintenance]]="yes",IF(Table1[[#This Row],[End Contract]]="","no",IF(TODAY()<=Table1[[#This Row],[End Contract]],"yes","no")),"no") -> yes | AA13: - | AB13: Tarifa
A14: 12 | B14: NC Logistica | C14: Natureza Em Congelados, Armazenagem e Comercialização de Produtos Alimentares Lda | D14: 505185016 | E14: Estrada Nacional 10, Alverca Park, Corpo E, Fracção Ao 2619-501 Alverca do Ribatejo | H14: 385 | I14: ESCO | J14: Solcorelios | K14: 15 | L14: =Table1[[#This Row],[Duration]]*12 -> 180 | N14: =IF(AND(Table1[[#This Row],[ Type of Contract]]="ESCO",Table1[[#This Row],[Status Detail]]="ACTIVE"),"yes","no") -> no | R14: CANCELLED | S14: Eurico do Carmo Cid | T14: Gerente | U14: euricocid@nclogistica.pt / filipacid@nclogistica.pt / fabianarodrigues@nclogistica.pt | V14: 219577123 | W14: =IF(Table1[[#This Row],[Maintenance]]="yes",IF(OR(Table1[[#This Row],[Start Contract]]="",Table1[[#This Row],[Duration Month2]]=""),"",EDATE(Table1[[#This Row],[Start Contract]],Table1[[#This Row],[Duration Month2]])),"-") -> - | X14: =IF(OR((W14=""),(W14="-")),"",YEAR(Table1[[#This Row],[End Contract]])) | Y14: =IF(Table1[[#This Row],[Maintenance]]="yes",IF(Table1[[#This Row],[End Contract]]="","no",IF(TODAY()<=Table1[[#This Row],[End Contract]],"yes","no")),"no") -> no
A15: 13 | B15: Marmo J | C15: Marmo J - Exportação, Importação, Mármores Unipessoal Lda | D15: 503995762 | E15: Avenida da Aviação Portuguesa, Nº 55, Fação 2715-140 Pêro Pinheiro | F15: Sintra | G15: 256 | H15: 101.12 | I15: ESCO | J15: Solcorelios | K15: 15 | L15: =Table1[[#This Row],[Duration]]*12 -> 180 | M15: 44287 | N15: =IF(AND(Table1[[#This Row],[ Type of Contract]]="ESCO",Table1[[#This Row],[Status Detail]]="ACTIVE"),"yes","no") -> yes | O15: Sandwich | P15: Escada | R15: ACTIVE | S15: Jorge Manuel Dos Santos Bernardes | T15: Gerente | U15: mara.cruz@marmoj.pt | V15: 912242073 | W15: =IF(Table1[[#This Row],[Maintenance]]="yes",IF(OR(Table1[[#This Row],[Start Contract]]="",Table1[[#This Row],[Duration Month2]]=""),"",EDATE(Table1[[#This Row],[Start Contract]],Table1[[#This Row],[Duration Month2]])),"-") -> 49766 | X15: =IF(OR((W15=""),(W15="-")),"",YEAR(Table1[[#This Row],[End Contract]])) -> 2036 | Y15: =IF(Table1[[#This Row],[Maintenance]]="yes",IF(Table1[[#This Row],[End Contract]]="","no",IF(TODAY()<=Table1[[#This Row],[End Contract]],"yes","no")),"no") -> yes | AA15: - | AB15: Tarifa
A16: 14 | B16: Roufimar | C16: Roufimar Industria de Marmores, S.A | D16: 501782265 | E16: Rua das Piçarras, 37, Maceira 2715-646 Maceira | F16: Sintra | G16: 475 | H16: 187.63 | I16: ESCO | J16: Solcorelios | K16: 15 | L16: =Table1[[#This Row],[Duration]]*12 -> 180 | M16: 44287 | N16: =IF(AND(Table1[[#This Row],[ Type of Contract]]="ESCO",Table1[[#This Row],[Status Detail]]="ACTIVE"),"yes","no") -> yes | O16: Sandwich | P16: Escada | R16: ACTIVE | S16: Arnaldo José Bordalo Roussado Ricardo | T16: Presidente | U16: info@roufinar.com | V16: 969056490 963685277 | W16: =IF(Table1[[#This Row],[Maintenance]]="yes",IF(OR(Table1[[#This Row],[Start Contract]]="",Table1[[#This Row],[Duration Month2]]=""),"",EDATE(Table1[[#This Row],[Start Contract]],Table1[[#This Row],[Duration Month2]])),"-") -> 49766 | X16: =IF(OR((W16=""),(W16="-")),"",YEAR(Table1[[#This Row],[End Contract]])) -> 2036 | Y16: =IF(Table1[[#This Row],[Maintenance]]="yes",IF(Table1[[#This Row],[End Contract]]="","no",IF(TODAY()<=Table1[[#This Row],[End Contract]],"yes","no")),"no") -> yes | AA16: - | AB16: Tarifa
A17: 15 | B17: Viarco | C17: Viarco-Industria de Lapis Lda | D17: 500751722 | E17: R Jaime Afreixo 533 3700-144 Sao Joao Madeira Codex | F17: Aveiro | G17: 76 | H17: 30.02 | I17: ESCO | J17: Solcorelios | K17: 15 | L17: =Table1[[#This Row],[Duration]]*12 -> 180 | M17: 44317 | N17: =IF(AND(Table1[[#This Row],[ Type of Contract]]="ESCO",Table1[[#This Row],[Status Detail]]="ACTIVE"),"yes","no") -> yes | O17: Sandwich | P17: Escada | R17: ACTIVE | S17: José Miguel Vieira Araújo Riobom dos Santos | T17: Gerente | U17: geral@viarco.pt / anacosta@viarco.pt | V17: 918302947 | W17: =IF(Table1[[#This Row],[Maintenance]]="yes",IF(OR(Table1[[#This Row],[Start Contract]]="",Table1[[#This Row],[Duration Month2]]=""),"",EDATE(Table1[[#This Row],[Start Contract]],Table1[[#This Row],[Duration Month2]])),"-") -> 49796 | X17: =IF(OR((W17=""),(W17="-")),"",YEAR(Table1[[#This Row],[End Contract]])) -> 2036 | Y17: =IF(Table1[[#This Row],[Maintenance]]="yes",IF(Table1[[#This Row],[End Contract]]="","no",IF(TODAY()<=Table1[[#This Row],[End Contract]],"yes","no")),"no") -> yes | AA17: - | AB17: Tarifa
A18: 16 | B18: O Zé Pacheco | C18: Gadelho de Castro, S.A | D18: 513203524 | E18: Rua D. António Castro Meireles, 907 4435-666 Baguim do Monte | F18: Porto | G18: 75 | H18: 29.625 | I18: ESCO | J18: Solcorelios | K18: 15 | L18: =Table1[[#This Row],[Duration]]*12 -> 180 | M18: 44531 | N18: =IF(AND(Table1[[#This Row],[ Type of Contract]]="ESCO",Table1[[#This Row],[Status Detail]]="ACTIVE"),"yes","no") -> yes | O18: Cobertura + Telha | P18: Escada | R18: ACTIVE | S18: António Castro de Jesus Gadelho Diogo Gadelho | T18: Administrador Único | U18: geral@ozepacheco.pt | V18: 915913810 | W18: =IF(Table1[[#This Row],[Maintenance]]="yes",IF(OR(Table1[[#This Row],[Start Contract]]="",Table1[[#This Row],[Duration Month2]]=""),"",EDATE(Table1[[#This Row],[Start Contract]],Table1[[#This Row],[Duration Month2]])),"-") -> 50010 | X18: =IF(OR((W18=""),(W18="-")),"",YEAR(Table1[[#This Row],[End Contract]])) -> 2036 | Y18: =IF(Table1[[#This Row],[Maintenance]]="yes",IF(Table1[[#This Row],[End Contract]]="","no",IF(TODAY()<=Table1[[#This Row],[End Contract]],"yes","no")),"no") -> yes | AA18: - | AB18: Tarifa
A19: 17 | B19: Amadois | C19: Amadois-Calçado Lda | D19: 502480335 | E19: Avenida Juventude Desportiva Carregosense, Nº 202 3720-018 Carregosa Oaz | F19: Arouca | G19: 144 | H19: 64.6 | I19: ESCO | J19: Solcorelios | K19: 7 | L19: =Table1[[#This Row],[Duration]]*12 -> 84 | M19: 44348 | N19: =IF(AND(Table1[[#This Row],[ Type of Contract]]="ESCO",Table1[[#This Row],[Status Detail]]="ACTIVE"),"yes","no") -> yes | O19: Sandwich | P19: Escada | R19: ACTIVE | S19: Paulo André Aguiar de Melo Almeida Miguel Melo | T19: Gerente | U19: mmelo@cruzeiro.pt | V19: 924434110 | W19: =IF(Table1[[#This Row],[Maintenance]]="yes",IF(OR(Table1[[#This Row],[Start Contract]]="",Table1[[#This Row],[Duration Month2]]=""),"",EDATE(Table1[[#This Row],[Start Contract]],Table1[[#This Row],[Duration Month2]])),"-") -> 46905 | X19: =IF(OR((W19=""),(W19="-")),"",YEAR(Table1[[#This Row],[End Contract]])) -> 2028 | Y19: =IF(Table1[[#This Row],[Maintenance]]="yes",IF(Table1[[#This Row],[End Contract]]="","no",IF(TODAY()<=Table1[[#This Row],[End Contract]],"yes","no")),"no") -> yes | AA19: - | AB19: Tarifa
A20: 18 | B20: Transportes Rapido | C20: Sociedade de Transportes Poiarense Lda | D20: 500269203 | E20: Zona Industrial de São Miguel Lts 33 e 34 3350-214 São Miguel de Poiares | F20: Coimbra | G20: 192 | H20: 85.5 | I20: ESCO | J20: Solcorelios | K20: 8 | L20: =Table1[[#This Row],[Duration]]*12 -> 96 | M20: 44317 | N20: =IF(AND(Table1[[#This Row],[ Type of Contract]]="ESCO",Table1[[#This Row],[Status Detail]]="ACTIVE"),"yes","no") -> yes | O20: Sandwich | P20: Escada | R20: ACTIVE | S20: Luisa Maria Henriques Simões / Jose Eduardo Henriques Simões / Vitor Fernando Cardoso De Carvalho | T20: Gerentes | U20: luisa.simoes@transportesrapido.com / mario.almeida@transportesrapido.com | V20: 966631463 | W20: =IF(Table1[[#This Row],[Maintenance]]="yes",IF(OR(Table1[[#This Row],[Start Contract]]="",Table1[[#This Row],[Duration Month2]]=""),"",EDATE(Table1[[#This Row],[Start Contract]],Table1[[#This Row],[Duration Month2]])),"-") -> 47239 | X20: =IF(OR((W20=""),(W20="-")),"",YEAR(Table1[[#This Row],[End Contract]])) -> 2029 | Y20: =IF(Table1[[#This Row],[Maintenance]]="yes",IF(Table1[[#This Row],[End Contract]]="","no",IF(TODAY()<=Table1[[#This Row],[End Contract]],"yes","no")),"no") -> yes | AA20: - | AB20: Tarifa
A21: 19 | B21: Granetos | C21: Granetos-Mármores e Granitos, S.A | D21: 501150617 | E21: Covão do Coelho 2395-001 Minde | F21: Leiria | G21: 360 | H21: 163.8 | I21: ESCO BUYOUT | J21: Solcorelios | K21: 15 | L21: =Table1[[#This Row],[Duration]]*12 -> 180 | M21: 44440 | N21: =IF(AND(Table1[[#This Row],[ Type of Contract]]="ESCO",Table1[[#This Row],[Status Detail]]="ACTIVE"),"yes","no") -> no | O21: Sandwich | P21: Escada | R21: ACTIVE | S21: Madalena Da Conceição Castanheira Neto Cerejeira | T21: Administrador | U21: miguelcerejeira@granetos.pt | V21: 249 840 579 | W21: =IF(Table1[[#This Row],[Maintenance]]="yes",IF(OR(Table1[[#This Row],[Start Contract]]="",Table1[[#This Row],[Duration Month2]]=""),"",EDATE(Table1[[#This Row],[Start Contract]],Table1[[#This Row],[Duration Month2]])),"-") -> - | X21: =IF(OR((W21=""),(W21="-")),"",YEAR(Table1[[#This Row],[End Contract]])) | Y21: =IF(Table1[[#This Row],[Maintenance]]="yes",IF(Table1[[#This Row],[End Contract]]="","no",IF(TODAY()<=Table1[[#This Row],[End Contract]],"yes","no")),"no") -> no
A22: 20 | B22: Queijaria Inácio Corvelo | C22: Inácio José Vinhas Corvelo | D22: 196141494 | E22: Rua Estacão 9168, Rio De Moinhos Borba, 7150-368 Borba | F22: Évora | G22: 108 | H22: 42.7 | I22: EPC | J22: Cliente | K22: 0 | L22: =Table1[[#This Row],[Duration]]*12 -> 0 | M22: - | N22: =IF(AND(Table1[[#This Row],[ Type of Contract]]="ESCO",Table1[[#This Row],[Status Detail]]="ACTIVE"),"yes","no") -> no | O22: Sandwich | P22: Escada | Q22: To discuss with Oscar | R22: ACTIVE | S22: Inácio José Vinhas Corvelo | T22: Gerente | V22: 961302782 | W22: =IF(Table1[[#This Row],[Maintenance]]="yes",IF(OR(Table1[[#This Row],[Start Contract]]="",Table1[[#This Row],[Duration Month2]]=""),"",EDATE(Table1[[#This Row],[Start Contract]],Table1[[#This Row],[Duration Month2]])),"-") -> - | X22: =IF(OR((W22=""),(W22="-")),"",YEAR(Table1[[#This Row],[End Contract]])) | Y22: =IF(Table1[[#This Row],[Maintenance]]="yes",IF(Table1[[#This Row],[End Contract]]="","no",IF(TODAY()<=Table1[[#This Row],[End Contract]],"yes","no")),"no") -> no
A23: 21 | B23: Topeca | C23: Topeca-Produtos de Construção Civil Lda | D23: 502782374 | E23: Cercal 2490-115 Cercal | F23: Leiria | G23: 160 | H23: 72.8 | I23: EPC | J23: Cliente | K23: 1 | L23: =Table1[[#This Row],[Duration]]*12 -> 12 | M23: 46179 | N23: yes | O23: Sandwich | P23: Escada | Q23: Maintenance discussed yearly with the client | R23: ACTIVE | S23: Francisco Ferreira Nunes César Nunes | T23: Gerente | U23: cesar.nunes@topeca.pt | V23: 938095499 | W23: =IF(Table1[[#This Row],[Maintenance]]="yes",IF(OR(Table1[[#This Row],[Start Contract]]="",Table1[[#This Row],[Duration Month2]]=""),"",EDATE(Table1[[#This Row],[Start Contract]],Table1[[#This Row],[Duration Month2]])),"-") -> 46544 | X23: =IF(OR((W23=""),(W23="-")),"",YEAR(Table1[[#This Row],[End Contract]])) -> 2027 | Y23: =IF(Table1[[#This Row],[Maintenance]]="yes",IF(Table1[[#This Row],[End Contract]]="","no",IF(TODAY()<=Table1[[#This Row],[End Contract]],"yes","no")),"no") -> yes | Z23: Sem certeza na quantidade de anos, imagino que seja 1
A24: 22 | B24: Mindtrooper | C24: Mindtrooper, Unipessoal, Limitada | D24: 509875874 | E24: Rua Antonio Bravo, N.0 140 | F24: Lisboa | H24: 140 | I24: EPC | J24: Cliente | K24: 0 | L24: =Table1[[#This Row],[Duration]]*12 -> 0 | M24: - | N24: =IF(AND(Table1[[#This Row],[ Type of Contract]]="ESCO",Table1[[#This Row],[Status Detail]]="ACTIVE"),"yes","no") -> no | R24: ACTIVE | W24: =IF(Table1[[#This Row],[Maintenance]]="yes",IF(OR(Table1[[#This Row],[Start Contract]]="",Table1[[#This Row],[Duration Month2]]=""),"",EDATE(Table1[[#This Row],[Start Contract]],Table1[[#This Row],[Duration Month2]])),"-") -> - | X24: =IF(OR((W24=""),(W24="-")),"",YEAR(Table1[[#This Row],[End Contract]])) | Y24: =IF(Table1[[#This Row],[Maintenance]]="yes",IF(Table1[[#This Row],[End Contract]]="","no",IF(TODAY()<=Table1[[#This Row],[End Contract]],"yes","no")),"no") -> no
A25: 23 | B25: Heden | C25: Liveworks, Lda | D25: 514345250 | E25: Doca Jardim do Tabaco, Terminal de Cruzeiros de Lisboa, Edifício Ne, 1º Piso 1100-651 Lisboa | F25: Lisboa | G25: 48 | H25: 18 | I25: EPC | J25: Cliente | K25: 0 | L25: =Table1[[#This Row],[Duration]]*12 -> 0 | M25: 44582 | N25: =IF(AND(Table1[[#This Row],[ Type of Contract]]="ESCO",Table1[[#This Row],[Status Detail]]="ACTIVE"),"yes","no") -> no | O25: Cobertura | P25: Escada | Q25: Maintenance discussed yearly with the client | R25: ACTIVE | S25: Manuel Bastos | U25: manuel@heden.co | V25: 919237074 | W25: =IF(Table1[[#This Row],[Maintenance]]="yes",IF(OR(Table1[[#This Row],[Start Contract]]="",Table1[[#This Row],[Duration Month2]]=""),"",EDATE(Table1[[#This Row],[Start Contract]],Table1[[#This Row],[Duration Month2]])),"-") -> - | X25: =IF(OR((W25=""),(W25="-")),"",YEAR(Table1[[#This Row],[End Contract]])) | Y25: =IF(Table1[[#This Row],[Maintenance]]="yes",IF(Table1[[#This Row],[End Contract]]="","no",IF(TODAY()<=Table1[[#This Row],[End Contract]],"yes","no")),"no") -> no
A26: 24 | B26: O Bolo do Caco | C26: Horizontes Renovados Lda | D26: 508975913 | E26: Rua Vicente Vaz das Vacas, Nº 22 8500-746 Portimão | F26: Faro | H26: 42.7 | I26: EPC | J26: Cliente | K26: 0 | L26: =Table1[[#This Row],[Duration]]*12 -> 0 | M26: 44922 | N26: =IF(AND(Table1[[#This Row],[ Type of Contract]]="ESCO",Table1[[#This Row],[Status Detail]]="ACTIVE"),"yes","no") -> no | R26: CANCELLED | S26: Paulo Pedrosa | T26: Gerente | W26: =IF(Table1[[#This Row],[Maintenance]]="yes",IF(OR(Table1[[#This Row],[Start Contract]]="",Table1[[#This Row],[Duration Month2]]=""),"",EDATE(Table1[[#This Row],[Start Contract]],Table1[[#This Row],[Duration Month2]])),"-") -> - | X26: =IF(OR((W26=""),(W26="-")),"",YEAR(Table1[[#This Row],[End Contract]])) | Y26: =IF(Table1[[#This Row],[Maintenance]]="yes",IF(Table1[[#This Row],[End Contract]]="","no",IF(TODAY()<=Table1[[#This Row],[End Contract]],"yes","no")),"no") -> no
A27: 25 | B27: Betafiel | C27: Betafiel-Artefactos de Betão de Penafiel S.A | D27: 500782016 | E27: Tapadinho 4560-162 Guilhufe | H27: 85.5 | I27: ESCO | J27: Solcorelios | K27: 10 | L27: =Table1[[#This Row],[Duration]]*12 -> 120 | N27: =IF(AND(Table1[[#This Row],[ Type of Contract]]="ESCO",Table1[[#This Row],[Status Detail]]="ACTIVE"),"yes","no") -> no | R27: CANCELLED | S27: Carlos Manuel Paquim da Costa | T27: Presidente do conselho de administração | U27: administracao@betafiel.pt | W27: =IF(Table1[[#This Row],[Maintenance]]="yes",IF(OR(Table1[[#This Row],[Start Contract]]="",Table1[[#This Row],[Duration Month2]]=""),"",EDATE(Table1[[#This Row],[Start Contract]],Table1[[#This Row],[Duration Month2]])),"-") -> - | X27: =IF(OR((W27=""),(W27="-")),"",YEAR(Table1[[#This Row],[End Contract]])) | Y27: =IF(Table1[[#This Row],[Maintenance]]="yes",IF(Table1[[#This Row],[End Contract]]="","no",IF(TODAY()<=Table1[[#This Row],[End Contract]],"yes","no")),"no") -> no
A28: 26 | B28: Multiaves | C28: Multiaves-Avicola Internacional Lda | D28: 502882514 | E28: Caramulo 3475-031 Caramulo | F28: Tondela | G28: 152 | H28: 69.2 | I28: ESCO | J28: Solcorelios | K28: 15 | L28: =Table1[[#This Row],[Duration]]*12 -> 180 | M28: 44440 | N28: =IF(AND(Table1[[#This Row],[ Type of Contract]]="ESCO",Table1[[#This Row],[Status Detail]]="ACTIVE"),"yes","no") -> yes | O28: Solo | P28: Não é necessário | R28: ACTIVE | S28: Gonçalo José Sousa Ornellas de Avillez Pereira / João Maria Lopes de Figueiredo de Lacerda | T28: Gerentes | U28: g.avillez.pereira@multiaves.pt / joao.lacerda@ovoscaramulo.com | V28: 232.860.030 | W28: =IF(Table1[[#This Row],[Maintenance]]="yes",IF(OR(Table1[[#This Row],[Start Contract]]="",Table1[[#This Row],[Duration Month2]]=""),"",EDATE(Table1[[#This Row],[Start Contract]],Table1[[#This Row],[Duration Month2]])),"-") -> 49919 | X28: =IF(OR((W28=""),(W28="-")),"",YEAR(Table1[[#This Row],[End Contract]])) -> 2036 | Y28: =IF(Table1[[#This Row],[Maintenance]]="yes",IF(Table1[[#This Row],[End Contract]]="","no",IF(TODAY()<=Table1[[#This Row],[End Contract]],"yes","no")),"no") -> yes | AA28: 8760 | AB28: Fixa
A29: 27 | B29: ITM Moita | C29: Intervedros - Supermercados, Lda | D29: 513018590 | E29: Quinta de Santa Rosa 2860-050 Alhos Vedros | F29: Setúbal | G29: 408 | H29: 183.6 | I29: ESCO | J29: Solcorelios | K29: 7 | L29: =Table1[[#This Row],[Duration]]*12 -> 84 | M29: 44470 | N29: =IF(AND(Table1[[#This Row],[ Type of Contract]]="ESCO",Table1[[#This Row],[Status Detail]]="ACTIVE"),"yes","no") -> yes | O29: Sandwich | P29: Escada | R29: ACTIVE | S29: Hugo Almeida | T29: Gerente | U29: interuedrcs@gmail.com | V29: 968973531 | W29: =IF(Table1[[#This Row],[Maintenance]]="yes",IF(OR(Table1[[#This Row],[Start Contract]]="",Table1[[#This Row],[Duration Month2]]=""),"",EDATE(Table1[[#This Row],[Start Contract]],Table1[[#This Row],[Duration Month2]])),"-") -> 47027 | X29: =IF(OR((W29=""),(W29="-")),"",YEAR(Table1[[#This Row],[End Contract]])) -> 2028 | Y29: =IF(Table1[[#This Row],[Maintenance]]="yes",IF(Table1[[#This Row],[End Contract]]="","no",IF(TODAY()<=Table1[[#This Row],[End Contract]],"yes","no")),"no") -> yes | AA29: - | AB29: Tarifa
A30: 28 | B30: Serralharia Vieira | C30: Serralharia Vieira Lda | D30: 501258060 | E30: Av. Estrada Real, N.º 1167-A 4620-787 Torno | F30: Porto | G30: 100 | H30: 45.5 | I30: ESCO | J30: Solcorelios | K30: 20 | L30: =Table1[[#This Row],[Duration]]*12 -> 240 | M30: 44470 | N30: =IF(AND(Table1[[#This Row],[ Type of Contract]]="ESCO",Table1[[#This Row],[Status Detail]]="ACTIVE"),"yes","no") -> yes | O30: Sandwich | P30: Escada | R30: ACTIVE | S30: Vitor Hugo Moreira Vieira | T30: Gerente | U30: Vítorserralhariavieira@hotmail.com | V30: 917528030 | W30: =IF(Table1[[#This Row],[Maintenance]]="yes",IF(OR(Table1[[#This Row],[Start Contract]]="",Table1[[#This Row],[Duration Month2]]=""),"",EDATE(Table1[[#This Row],[Start Contract]],Table1[[#This Row],[Duration Month2]])),"-") -> 51775 | X30: =IF(OR((W30=""),(W30="-")),"",YEAR(Table1[[#This Row],[End Contract]])) -> 2041 | Y30: =IF(Table1[[#This Row],[Maintenance]]="yes",IF(Table1[[#This Row],[End Contract]]="","no",IF(TODAY()<=Table1[[#This Row],[End Contract]],"yes","no")),"no") -> yes | AA30: - | AB30: Tarifa
A31: 29 | B31: Colégio Nossa Senhora da Apresentação | C31: Colégio Diocesano de Nossa Senhora da Apresentação | D31: 502786078 | E31: Aveiro - Vagos - | F31: Aveiro | G31: 340 | H31: =210*0.53 -> 111.3 | I31: ESCO | J31: Solcorelios | K31: 15 | L31: =Table1[[#This Row],[Duration]]*12 -> 180 | M31: 44501 | N31: =IF(AND(Table1[[#This Row],[ Type of Contract]]="ESCO",Table1[[#This Row],[Status Detail]]="ACTIVE"),"yes","no") -> yes | O31: Sandwich | P31: Escada Vertical | R31: ACTIVE | S31: Luís Fernando Oliveira David Malta/Ricardo Silva | T31: Diretor | U31: luísolíveira@colegiocalcao.org | V31: 931731853/925094080 | W31: =IF(Table1[[#This Row],[Maintenance]]="yes",IF(OR(Table1[[#This Row],[Start Contract]]="",Table1[[#This Row],[Duration Month2]]=""),"",EDATE(Table1[[#This Row],[Start Contract]],Table1[[#This Row],[Duration Month2]])),"-") -> 49980 | X31: =IF(OR((W31=""),(W31="-")),"",YEAR(Table1[[#This Row],[End Contract]])) -> 2036 | Y31: =IF(Table1[[#This Row],[Maintenance]]="yes",IF(Table1[[#This Row],[End Contract]]="","no",IF(TODAY()<=Table1[[#This Row],[End Contract]],"yes","no")),"no") -> yes | AA31: - | AB31: Tarifa
A32: 30 | B32: Absorvalor | C32: Absorvalor Lda | D32: 507685733 | E32: Rua da Ferraria, Chãs 2415-178 Regueira de Pontes | F32: Leiria | G32: 576 | H32: 254.8 | I32: ESCO BUYOUT | J32: Solcorelios | K32: 15 | L32: =Table1[[#This Row],[Duration]]*12 -> 180 | M32: 44531 | N32: =IF(AND(Table1[[#This Row],[ Type of Contract]]="ESCO",Table1[[#This Row],[Status Detail]]="ACTIVE"),"yes","no") -> no | O32: Sandwich | P32: Escada | R32: ACTIVE | S32: Muhammad Abdul Satar / Bernardino Manuel Amaro dos Santos Carla | T32: Gerentes | V32: 910983469 | W32: =IF(Table1[[#This Row],[Maintenance]]="yes",IF(OR(Table1[[#This Row],[Start Contract]]="",Table1[[#This Row],[Duration Month2]]=""),"",EDATE(Table1[[#This Row],[Start Contract]],Table1[[#This Row],[Duration Month2]])),"-") -> - | X32: =IF(OR((W32=""),(W32="-")),"",YEAR(Table1[[#This Row],[End Contract]])) | Y32: =IF(Table1[[#This Row],[Maintenance]]="yes",IF(Table1[[#This Row],[End Contract]]="","no",IF(TODAY()<=Table1[[#This Row],[End Contract]],"yes","no")),"no") -> no
A33: 31 | B33: MC Rios | C33: M.C. Rios, S.A | D33: 502893575 | E33: Lugar do Areeiro 3850-200 Albergaria-A-Velha | H33: 172.9 | I33: ESCO | J33: Solcorelios | K33: 15 | L33: =Table1[[#This Row],[Duration]]*12 -> 180 | N33: =IF(AND(Table1[[#This Row],[ Type of Contract]]="ESCO",Table1[[#This Row],[Status Detail]]="ACTIVE"),"yes","no") -> no | R33: CANCELLED | S33: Maria Leonor Duarte Rios Pires / Carlos Alberto Rodrigues Duarte Rios | T33: Vogal | W33: =IF(Table1[[#This Row],[Maintenance]]="yes",IF(OR(Table1[[#This Row],[Start Contract]]="",Table1[[#This Row],[Duration Month2]]=""),"",EDATE(Table1[[#This Row],[Start Contract]],Table1[[#This Row],[Duration Month2]])),"-") -> - | X33: =IF(OR((W33=""),(W33="-")),"",YEAR(Table1[[#This Row],[End Contract]])) | Y33: =IF(Table1[[#This Row],[Maintenance]]="yes",IF(Table1[[#This Row],[End Contract]]="","no",IF(TODAY()<=Table1[[#This Row],[End Contract]],"yes","no")),"no") -> no
A34: 32 | B34: VCP | C34: Vidraria Central do Porto, S.A | D34: 503502707 | E34: Avenida D. Miguel, 340, Pavilhão E, Zona Industrial Baguim do Monte 4435-678 Baguim do Monte - Gondomar | F34: Porto | G34: 80 | H34: 36.4 | I34: EPC | J34: Cliente | K34: 0 | L34: =Table1[[#This Row],[Duration]]*12 -> 0 | M34: - | N34: =IF(AND(Table1[[#This Row],[ Type of Contract]]="ESCO",Table1[[#This Row],[Status Detail]]="ACTIVE"),"yes","no") -> no | O34: Sandwich | P34: Escada | Q34: Maintenance discussed yearly with the client | R34: ACTIVE | S34: Nuno Amilcar Fragoso / Vítor Manuel da Fonseca Pereira | T34: Presidente / Vogal | W34: =IF(Table1[[#This Row],[Maintenance]]="yes",IF(OR(Table1[[#This Row],[Start Contract]]="",Table1[[#This Row],[Duration Month2]]=""),"",EDATE(Table1[[#This Row],[Start Contract]],Table1[[#This Row],[Duration Month2]])),"-") -> - | X34: =IF(OR((W34=""),(W34="-")),"",YEAR(Table1[[#This Row],[End Contract]])) | Y34: =IF(Table1[[#This Row],[Maintenance]]="yes",IF(Table1[[#This Row],[End Contract]]="","no",IF(TODAY()<=Table1[[#This Row],[End Contract]],"yes","no")),"no") -> no
A35: 33 | B35: Sicobrita | C35: Sicobrita - Extracção e Britagem de Pedra S.A | D35: 501277676 | E35: R de Santa Luzia Nº 22 - Sala 32 3100-483 Pombal | F35: Pombal | G35: 1824 | H35: =1824*0.45 -> 820.8 | I35: ESCO | J35: Solcorelios | K35: 15 | L35: =Table1[[#This Row],[Duration]]*12 -> 180 | M35: 44743 | N35: =IF(AND(Table1[[#This Row],[ Type of Contract]]="ESCO",Table1[[#This Row],[Status Detail]]="ACTIVE"),"yes","no") -> yes | O35: Solo | P35: Não é necessário | R35: ACTIVE | S35: Armando Jose Manuel Bugalhão Carrilho Patricio Artur | T35: Presidente do Conselho de Administração | U35: armando.vieira@sicobrita.pt | V35: 969507300 916036244 963063582 963642561 | W35: =IF(Table1[[#This Row],[Maintenance]]="yes",IF(OR(Table1[[#This Row],[Start Contract]]="",Table1[[#This Row],[Duration Month2]]=""),"",EDATE(Table1[[#This Row],[Start Contract]],Table1[[#This Row],[Duration Month2]])),"-") -> 50222 | X35: =IF(OR((W35=""),(W35="-")),"",YEAR(Table1[[#This Row],[End Contract]])) -> 2037 | Y35: =IF(Table1[[#This Row],[Maintenance]]="yes",IF(Table1[[#This Row],[End Contract]]="","no",IF(TODAY()<=Table1[[#This Row],[End Contract]],"yes","no")),"no") -> yes | AA35: - | AB35: Tarifa
A36: 34 | B36: Mirandesa | C36: Cooperativa Agro-Pecuária Mirandesa Crl | D36: 501416382 | E36: Zona Industrial de Vimioso - Lote 42/45 5230-284 Vimioso | F36: Bragança - Vimioso | G36: 144 | H36: 76.32 | I36: ESCO | J36: Solcorelios | K36: 15 | L36: =Table1[[#This Row],[Duration]]*12 -> 180 | M36: 44501 | N36: =IF(AND(Table1[[#This Row],[ Type of Contract]]="ESCO",Table1[[#This Row],[Status Detail]]="ACTIVE"),"yes","no") -> yes | O36: Sandwich | P36: Escada | R36: ACTIVE | S36: Nuno Paulo António Manuel Luís / José Abílio João | T36: Presidente / Tesoureiro | U36: nunorpaulo@mirandesa.pt | V36: 966969869 | W36: =IF(Table1[[#This Row],[Maintenance]]="yes",IF(OR(Table1[[#This Row],[Start Contract]]="",Table1[[#This Row],[Duration Month2]]=""),"",EDATE(Table1[[#This Row],[Start Contract]],Table1[[#This Row],[Duration Month2]])),"-") -> 49980 | X36: =IF(OR((W36=""),(W36="-")),"",YEAR(Table1[[#This Row],[End Contract]])) -> 2036 | Y36: =IF(Table1[[#This Row],[Maintenance]]="yes",IF(Table1[[#This Row],[End Contract]]="","no",IF(TODAY()<=Table1[[#This Row],[End Contract]],"yes","no")),"no") -> yes | AA36: - | AB36: Tarifa
A37: 35 | B37: Jovi-Sola | C37: Jovi-Sola – Pré fabricados para calçado, Lda | D37: 504277219 | E37: Rua Dom Dinis, N.º 110 3700-466 Arrifana Vfr | H37: 45.1 | I37: ESCO | J37: Solcorelios | K37: 15 | L37: =Table1[[#This Row],[Duration]]*12 -> 180 | N37: =IF(AND(Table1[[#This Row],[ Type of Contract]]="ESCO",Table1[[#This Row],[Status Detail]]="ACTIVE"),"yes","no") -> no | R37: CANCELLED | S37: Vítor Manuel Francisco | T37: Gerente | U37: jovi-sola@sapo.pt | W37: =IF(Table1[[#This Row],[Maintenance]]="yes",IF(OR(Table1[[#This Row],[Start Contract]]="",Table1[[#This Row],[Duration Month2]]=""),"",EDATE(Table1[[#This Row],[Start Contract]],Table1[[#This Row],[Duration Month2]])),"-") -> - | X37: =IF(OR((W37=""),(W37="-")),"",YEAR(Table1[[#This Row],[End Contract]])) | Y37: =IF(Table1[[#This Row],[Maintenance]]="yes",IF(Table1[[#This Row],[End Contract]]="","no",IF(TODAY()<=Table1[[#This Row],[End Contract]],"yes","no")),"no") -> no
A38: 36 | B38: Joaquim Pinheiro Santos | C38: JOAQUIM PINHEIRO SANTOS,SUCESSORES LDA | D38: 500152624 | E38: Vila Moreira (39.471324, -8.675141) | F38: Santarém | G38: 413 | H38: 218.9 | I38: EPC | J38: Cliente | K38: 2 | L38: =Table1[[#This Row],[Duration]]*12 -> 24 | M38: 45108 | N38: yes | O38: Sandwich | P38: Escada | Q38: To discuss with the client | R38: ACTIVE | S38: Nuno Santos | U38: curtir@sapo.pt | V38: 939720430 | W38: =IF(Table1[[#This Row],[Maintenance]]="yes",IF(OR(Table1[[#This Row],[Start Contract]]="",Table1[[#This Row],[Duration Month2]]=""),"",EDATE(Table1[[#This Row],[Start Contract]],Table1[[#This Row],[Duration Month2]])),"-") -> 45839 | X38: =IF(OR((W38=""),(W38="-")),"",YEAR(Table1[[#This Row],[End Contract]])) -> 2025 | Y38: =IF(Table1[[#This Row],[Maintenance]]="yes",IF(Table1[[#This Row],[End Contract]]="","no",IF(TODAY()<=Table1[[#This Row],[End Contract]],"yes","no")),"no") -> no | Z38: Não ha registo de contrato estar renovado
A39: 37 | B39: Ferraz & Ferreira | C39: Ferraz & Ferreira, Lda. | D39: 500876746 | E39: Rua do Padrão, 140 4760-743 Vilarinho das Cambas | F39: Vila Nova de Famalicão | G39: 272 | H39: =(44+80+148)*0.53 -> 144.16 | I39: ESCO | J39: Solcorelios | K39: 10 | L39: =Table1[[#This Row],[Duration]]*12 -> 120 | M39: 44713 | N39: =IF(AND(Table1[[#This Row],[ Type of Contract]]="ESCO",Table1[[#This Row],[Status Detail]]="ACTIVE"),"yes","no") -> yes | O39: Cobertura + Sandwich | P39: Escada | R39: ACTIVE | S39: Paula Ana Maria Fluckiger Ferraz Coutinho | T39: Gerente | U39: paulaferrazferreira.com.pt | V39: 252301350 252301351 914981896 914933459 | W39: =IF(Table1[[#This Row],[Maintenance]]="yes",IF(OR(Table1[[#This Row],[Start Contract]]="",Table1[[#This Row],[Duration Month2]]=""),"",EDATE(Table1[[#This Row],[Start Contract]],Table1[[#This Row],[Duration Month2]])),"-") -> 48366 | X39: =IF(OR((W39=""),(W39="-")),"",YEAR(Table1[[#This Row],[End Contract]])) -> 2032 | Y39: =IF(Table1[[#This Row],[Maintenance]]="yes",IF(Table1[[#This Row],[End Contract]]="","no",IF(TODAY()<=Table1[[#This Row],[End Contract]],"yes","no")),"no") -> yes | AA39: - | AB39: Tarifa
A40: 38 | B40: LIDL | C40: Lidl & Companhia | D40: 503340855 | G40: 316(bragança)+332(lousã)+33(moução)+316(porto)+333(tomar)+333(covilhã)+333(viana do castelo) | H40: 873.81 | I40: EPC | J40: Cliente | K40: 0 | L40: =Table1[[#This Row],[Duration]]*12 -> 0 | M40: - | N40: =IF(AND(Table1[[#This Row],[ Type of Contract]]="ESCO",Table1[[#This Row],[Status Detail]]="ACTIVE"),"yes","no") -> no | O40: Cobertura | P40: Escada | R40: ACTIVE | W40: =IF(Table1[[#This Row],[Maintenance]]="yes",IF(OR(Table1[[#This Row],[Start Contract]]="",Table1[[#This Row],[Duration Month2]]=""),"",EDATE(Table1[[#This Row],[Start Contract]],Table1[[#This Row],[Duration Month2]])),"-") -> - | X40: =IF(OR((W40=""),(W40="-")),"",YEAR(Table1[[#This Row],[End Contract]])) | Y40: =IF(Table1[[#This Row],[Maintenance]]="yes",IF(Table1[[#This Row],[End Contract]]="","no",IF(TODAY()<=Table1[[#This Row],[End Contract]],"yes","no")),"no") -> no
...

Sheet Venda do excedente
B1: Status | C1: Company Name | D1: Comercializador | E1: Tipo de Contrato | F1: Envio de Proposta | G1: Envio do Contrato | H1: Ass. do Contrato (Recebido do cliente) | I1: Envio p/ Comercializador | J1: Situação | K1: Duração (Mês) | L1: Data Inicio | M1: Data Final | N1: Observação
B2: =IF(J2="Não Tratar",4,IF(J2="Ativo",3,IF(J2="Aguardando",2,IF(J2="Certificado",1,IF(J2="Pendencias",0))))) -> 3 | C2: {=_xlfn._xlws.FILTER('Project Overview'!B:B,('Project Overview'!#REF!="ACTIVE")*('Project Overview'!#REF!="Com Injeção"))} -> #REF! | D2: Simples Energia | J2: Ativo | K2: 12 | L2: 44223 | M2: =EOMONTH(L2,K2) -> 44592
B3: =IF(J3="Não Tratar",4,IF(J3="Ativo",3,IF(J3="Aguardando",2,IF(J3="Certificado",1,IF(J3="Pendencias",0))))) -> 3 | D3: Simples Energia | J3: Ativo | K3: 12 | L3: 44360 | M3: =EOMONTH(L3,K3) -> 44742
B4: =IF(J4="Não Tratar",4,IF(J4="Ativo",3,IF(J4="Aguardando",2,IF(J4="Certificado",1,IF(J4="Pendencias",0))))) -> 3 | D4: Simples Energia | J4: Ativo | K4: 12 | L4: 44406 | M4: =EOMONTH(L4,K4) -> 44773
B5: =IF(J5="Não Tratar",4,IF(J5="Ativo",3,IF(J5="Aguardando",2,IF(J5="Certificado",1,IF(J5="Pendencias",0))))) -> 3 | D5: Simples Energia | J5: Ativo | K5: 12 | L5: 44341 | M5: =EOMONTH(L5,K5) -> 44712
B6: =IF(J6="Não Tratar",4,IF(J6="Ativo",3,IF(J6="Aguardando",2,IF(J6="Certificado",1,IF(J6="Pendencias",0))))) -> 4 | J6: Não Tratar
B7: =IF(J7="Não Tratar",4,IF(J7="Ativo",3,IF(J7="Aguardando",2,IF(J7="Certificado",1,IF(J7="Pendencias",0))))) -> 3 | D7: Simples Energia | J7: Ativo | K7: 12 | L7: 44295 | M7: =EOMONTH(L7,K7) -> 44681
B8: =IF(J8="Não Tratar",4,IF(J8="Ativo",3,IF(J8="Aguardando",2,IF(J8="Certificado",1,IF(J8="Pendencias",0))))) -> 3 | D8: Simples Energia | J8: Ativo | K8: 12 | L8: 44370 | M8: =EOMONTH(L8,K8) -> 44742
B9: =IF(J9="Não Tratar",4,IF(J9="Ativo",3,IF(J9="Aguardando",2,IF(J9="Certificado",1,IF(J9="Pendencias",0))))) -> 4 | D9: Simples Energia | G9: 44309 | J9: Não Tratar | K9: 12 | N9: Nunca enviou os documentos
B10: =IF(J10="Não Tratar",4,IF(J10="Ativo",3,IF(J10="Aguardando",2,IF(J10="Certificado",1,IF(J10="Pendencias",0))))) -> 3 | D10: Simples Energia Espanha | E10: Indexado | G10: 44519 | H10: 44586 | I10: 44586 | J10: Ativo | K10: 12 | L10: 44611 | M10: =EOMONTH(L10,K10) -> 44985 | N10: Foi solicitado novamento por email no dia 07.06.2021. Dia 22/06/2021. Liguei dia 01/07/2021. Contrato enviado 14/07/2021 e Procuração dia 09/07/2021.
B11: =IF(J11="Não Tratar",4,IF(J11="Ativo",3,IF(J11="Aguardando",2,IF(J11="Certificado",1,IF(J11="Pendencias",0))))) -> 3 | D11: Simples Energia | J11: Ativo | K11: 12 | L11: 44379 | M11: =EOMONTH(L11,K11) -> 44773
B12: =IF(J12="Não Tratar",4,IF(J12="Ativo",3,IF(J12="Aguardando",2,IF(J12="Certificado",1,IF(J12="Pendencias",0))))) -> 4 | D12: Contrato? | J12: Não Tratar | K12: 12 | N12: Vincent pediu para aguardar, não fazer nada até ele falar
B13: =IF(J13="Não Tratar",4,IF(J13="Ativo",3,IF(J13="Aguardando",2,IF(J13="Certificado",1,IF(J13="Pendencias",0))))) -> 3 | D13: Simples Energia | G13: 44293 | H13: 44321 | I13: 44326 | J13: Ativo | K13: 12 | L13: 44363 | M13: =EOMONTH(L13,K13) -> 44742
B14: =IF(J14="Não Tratar",4,IF(J14="Ativo",3,IF(J14="Aguardando",2,IF(J14="Certificado",1,IF(J14="Pendencias",0))))) -> 3 | D14: Simples Energia | E14: Indexado | G14: 44519 | J14: Ativo | K14: 12 | L14: 44572 | M14: =EOMONTH(L14,K14) -> 44957
B15: =IF(J15="Não Tratar",4,IF(J15="Ativo",3,IF(J15="Aguardando",2,IF(J15="Certificado",1,IF(J15="Pendencias",0))))) -> 3 | D15: LuzBoa | E15: Indexado | J15: Ativo | K15: 12 | L15: 44712 | M15: =EOMONTH(L15,K15) -> 45077
B16: =IF(J16="Não Tratar",4,IF(J16="Ativo",3,IF(J16="Aguardando",2,IF(J16="Certificado",1,IF(J16="Pendencias",0))))) -> 3 | D16: LuzBoa | E16: Indexado | G16: 44522 | H16: 44533 | I16: 44536 | J16: Ativo | K16: 12 | L16: 44561 | M16: =EOMONTH(L16,K16) -> 44926
B17: =IF(J17="Não Tratar",4,IF(J17="Ativo",3,IF(J17="Aguardando",2,IF(J17="Certificado",1,IF(J17="Pendencias",0))))) -> 3 | D17: LuzBoa | E17: Indexado | G17: 44605 | J17: Ativo | K17: 12 | L17: 44653 | M17: =EOMONTH(L17,K17) -> 45046
B18: =IF(J18="Não Tratar",4,IF(J18="Ativo",3,IF(J18="Aguardando",2,IF(J18="Certificado",1,IF(J18="Pendencias",0))))) -> 4 | J18: Não Tratar
B19: =IF(J19="Não Tratar",4,IF(J19="Ativo",3,IF(J19="Aguardando",2,IF(J19="Certificado",1,IF(J19="Pendencias",0))))) -> 3 | D19: Simples Energia Espanha | E19: Indexado | H19: 44537 | I19: 44547 | J19: Ativo | K19: 12 | L19: 44593 | M19: =EOMONTH(L19,K19) -> 44985
B20: =IF(J20="Não Tratar",4,IF(J20="Ativo",3,IF(J20="Aguardando",2,IF(J20="Certificado",1,IF(J20="Pendencias",0))))) -> 4 | J20: Não Tratar
B21: =IF(J21="Não Tratar",4,IF(J21="Ativo",3,IF(J21="Aguardando",2,IF(J21="Certificado",1,IF(J21="Pendencias",0))))) -> 4 | J21: Não Tratar
B22: =IF(J22="Não Tratar",4,IF(J22="Ativo",3,IF(J22="Aguardando",2,IF(J22="Certificado",1,IF(J22="Pendencias",0))))) -> 4 | J22: Não Tratar
B23: =IF(J23="Não Tratar",4,IF(J23="Ativo",3,IF(J23="Aguardando",2,IF(J23="Certificado",1,IF(J23="Pendencias",0))))) -> 3 | D23: - | J23: Ativo | K23: 12 | L23: 44712 | M23: =EOMONTH(L23,K23) -> 45077
B24: =IF(J24="Não Tratar",4,IF(J24="Ativo",3,IF(J24="Aguardando",2,IF(J24="Certificado",1,IF(J24="Pendencias",0))))) -> 3 | D24: LuzBoa | E24: Indexado | I24: 45106 | J24: Ativo | K24: 12 | L24: 44832 | M24: =EOMONTH(L24,K24) -> 45199
B25: =IF(J25="Não Tratar",4,IF(J25="Ativo",3,IF(J25="Aguardando",2,IF(J25="Certificado",1,IF(J25="Pendencias",0))))) -> 4 | J25: Não Tratar
B26: =IF(J26="Não Tratar",4,IF(J26="Ativo",3,IF(J26="Aguardando",2,IF(J26="Certificado",1,IF(J26="Pendencias",0))))) -> 3 | D26: LuzBoa | E26: Indexado | J26: Ativo | K26: 12 | L26: 44775 | M26: =EOMONTH(L26,K26) -> 45169
B27: =IF(J27="Não Tratar",4,IF(J27="Ativo",3,IF(J27="Aguardando",2,IF(J27="Certificado",1,IF(J27="Pendencias",0))))) -> 3 | D27: LuzBoa | E27: Indexado | G27: 44567 | H27: 44575 | I27: 44579 | J27: Ativo | K27: 12 | L27: 44607 | M27: =EOMONTH(L27,K27) -> 44985
B28: =IF(J28="Não Tratar",4,IF(J28="Ativo",3,IF(J28="Aguardando",2,IF(J28="Certificado",1,IF(J28="Pendencias",0))))) -> 3 | D28: EZU Energia | E28: Fixo | I28: 45105 | J28: Ativo | K28: 12 | L28: 45133 | M28: =EOMONTH(L28,K28) -> 45504 | N28: A Sicobrita 2 a única diferença é a data de inicio que é 19/07/2023
B29: =IF(J29="Não Tratar",4,IF(J29="Ativo",3,IF(J29="Aguardando",2,IF(J29="Certificado",1,IF(J29="Pendencias",0))))) -> 3 | D29: LuzBoa | E29: Indexado | J29: Ativo | K29: 12 | L29: 44722 | M29: =EOMONTH(L29,K29) -> 45107
B30: =IF(J30="Não Tratar",4,IF(J30="Ativo",3,IF(J30="Aguardando",2,IF(J30="Certificado",1,IF(J30="Pendencias",0))))) -> 3 | D30: LuzBoa | E30: Indexado | J30: Ativo | K30: 12 | L30: 44741 | M30: =EOMONTH(L30,K30) -> 45107
B31: =IF(J31="Não Tratar",4,IF(J31="Ativo",3,IF(J31="Aguardando",2,IF(J31="Certificado",1,IF(J31="Pendencias",0))))) -> 3 | D31: LuzBoa | E31: Indexado | J31: Ativo | K31: 12 | L31: 44790 | M31: =EOMONTH(L31,K31) -> 45169
B32: =IF(J32="Não Tratar",4,IF(J32="Ativo",3,IF(J32="Aguardando",2,IF(J32="Certificado",1,IF(J32="Pendencias",0))))) -> 4 | J32: Não Tratar
B33: =IF(J33="Não Tratar",4,IF(J33="Ativo",3,IF(J33="Aguardando",2,IF(J33="Certificado",1,IF(J33="Pendencias",0))))) -> 0 | J33: Pendencias
B34: =IF(J34="Não Tratar",4,IF(J34="Ativo",3,IF(J34="Aguardando",2,IF(J34="Certificado",1,IF(J34="Pendencias",0))))) -> 3 | D34: LuzBoa | E34: Indexado | G34: 44980 | H34: 44998 | I34: 45000 | J34: Ativo | K34: 12 | L34: 45049 | M34: =EOMONTH(L34,K34) -> 45443 | N34: Falta certificado para envio do contrato
B35: =IF(J35="Não Tratar",4,IF(J35="Ativo",3,IF(J35="Aguardando",2,IF(J35="Certificado",1,IF(J35="Pendencias",0))))) -> 3 | D35: LuzBoa | E35: Indexado | J35: Ativo | K35: 12 | L35: 44697 | M35: =EOMONTH(L35,K35) -> 45077 | N35: Trocou para Ezu em 30/10/2023
B36: =IF(J36="Não Tratar",4,IF(J36="Ativo",3,IF(J36="Aguardando",2,IF(J36="Certificado",1,IF(J36="Pendencias",0))))) -> 3 | D36: LuzBoa | E36: Indexado | J36: Ativo | K36: 12 | L36: 44696 | M36: =EOMONTH(L36,K36) -> 45077
B37: =IF(J37="Não Tratar",4,IF(J37="Ativo",3,IF(J37="Aguardando",2,IF(J37="Certificado",1,IF(J37="Pendencias",0))))) -> 3 | D37: LuzBoa | E37: Indexado | J37: Ativo | K37: 12 | L37: 44757 | M37: =EOMONTH(L37,K37) -> 45138
B38: =IF(J38="Não Tratar",4,IF(J38="Ativo",3,IF(J38="Aguardando",2,IF(J38="Certificado",1,IF(J38="Pendencias",0))))) -> 3 | D38: LuzBoa | E38: Indexado | J38: Ativo | K38: 12 | L38: 44782 | M38: =EOMONTH(L38,K38) -> 45169
B39: =IF(J39="Não Tratar",4,IF(J39="Ativo",3,IF(J39="Aguardando",2,IF(J39="Certificado",1,IF(J39="Pendencias",0))))) -> 3 | D39: LuzBoa | E39: Indexado | J39: Ativo | K39: 12 | L39: 44697 | M39: =EOMONTH(L39,K39) -> 45077
B40: =IF(J40="Não Tratar",4,IF(J40="Ativo",3,IF(J40="Aguardando",2,IF(J40="Certificado",1,IF(J40="Pendencias",0))))) -> 3 | D40: LuzBoa | E40: Indexado | G40: 44818 | H40: 44820 | I40: 44820 | J40: Ativo | K40: 12 | L40: 44860 | M40: =EOMONTH(L40,K40) -> 45230 | N40: Enviado dia 08/07/21 p/ Fabio e Certficado enviado 04/08/2021.
...

Sheet Validação Overview
A1: Validação do Project Overview
A2: Esta folha mostra linhas com dados em falta. Estado = REVER quando existe pelo menos uma falha.
A4: N° | B4: Project | C4: Company Name | D4: Status Detail | E4: Active Contract | F4: Falta projeto | G4: Falta empresa | H4: Falta NIF | I4: Falta localização | J4: Falta duração | K4: Falta start | L4: Falta email | M4: Falta Det Cobertura | N4: Falta Det Acesso | O4: Total falhas | P4: Estado | R4: Legenda
A5: =""&'Project Overview'!A2 -> 1 | B5: ='Project Overview'!B2 -> A Colmeia do Minho | C5: ='Project Overview'!C2 -> A Colmeia do Minho, S.A., | D5: ='Project Overview'!R2 -> ACTIVE | E5: ='Project Overview'!Y2 -> yes | F5: =IF(OR($A5="",$B5=""),1,0) -> 0 | G5: =IF($C5="",1,0) -> 0 | H5: =IF('Project Overview'!D2="",1,0) -> 0 | I5: =IF('Project Overview'!F2="",1,0) -> 0 | J5: =IF(AND($A5<>"",OR('Project Overview'!I2="ESCO",'Project Overview'!I2="EPC",'Project Overview'!I2="ESCO BUYOUT"),'Project Overview'!K2=""),1,0) -> 0 | K5: =IF(AND($A5<>"",'Project Overview'!M2=""),1,0) -> 0 | L5: =IF(AND($A5<>"",'Project Overview'!U2=""),1,0) -> 0 | M5: =IF(OR($A5="",'Project Overview'!O2="",'Project Overview'!O2="?"),1,0) -> 0 | N5: =IF(OR($A5="",'Project Overview'!P2="", 'Project Overview'!P2="?"),1,0) -> 0 | O5: =SUM(F5:N5) -> 0 | P5: =IF($A5="","",IF($O5=0,"OK","REVER")) -> OK | R5: OK | S5: Sem falhas
A6: =""&'Project Overview'!A3 -> 2 | B6: ='Project Overview'!B3 -> Florineve | C6: ='Project Overview'!C3 -> Florineve - Produção e Comércio de Flores de Corte | D6: ='Project Overview'!R3 -> ACTIVE | E6: ='Project Overview'!Y3 -> yes | F6: =IF(OR($A6="",$B6=""),1,0) -> 0 | G6: =IF($C6="",1,0) -> 0 | H6: =IF(AND($A6<>"",'Project Overview'!D3=""),1,0) -> 0 | I6: =IF(AND($A6<>"",'Project Overview'!F3=""),1,0) -> 0 | J6: =IF(AND($A6<>"",OR('Project Overview'!I3="ESCO",'Project Overview'!I3="EPC",'Project Overview'!I3="ESCO BUYOUT"),'Project Overview'!K3=""),1,0) -> 0 | K6: =IF(AND($A6<>"",'Project Overview'!M3=""),1,0) -> 0 | L6: =IF(AND($A6<>"",'Project Overview'!U3=""),1,0) -> 0 | M6: =IF(OR($A6="",'Project Overview'!O3="",'Project Overview'!O3="?"),1,0) -> 0 | N6: =IF(OR($A6="",'Project Overview'!P3="", 'Project Overview'!P3="?"),1,0) -> 0 | O6: =SUM(F6:N6) -> 0 | P6: =IF($A6="","",IF($O6=0,"OK","REVER")) -> OK | R6: REVER | S6: Faltam dados
A7: =""&'Project Overview'!A4 -> 3 | B7: ='Project Overview'!B4 -> Dialogos do Bosque | C7: ='Project Overview'!C4 -> Diálogos do Bosque, Unipessoal, LDA | D7: ='Project Overview'!R4 -> ACTIVE | E7: ='Project Overview'!Y4 -> yes | F7: =IF(OR($A7="",$B7=""),1,0) -> 0 | G7: =IF($C7="",1,0) -> 0 | H7: =IF(AND($A7<>"",'Project Overview'!D4=""),1,0) -> 0 | I7: =IF(AND($A7<>"",'Project Overview'!F4=""),1,0) -> 0 | J7: =IF(AND($A7<>"",OR('Project Overview'!I4="ESCO",'Project Overview'!I4="EPC",'Project Overview'!I4="ESCO BUYOUT"),'Project Overview'!K4=""),1,0) -> 0 | K7: =IF(AND($A7<>"",'Project Overview'!M4=""),1,0) -> 0 | L7: =IF(AND($A7<>"",'Project Overview'!U4=""),1,0) -> 0 | M7: =IF(OR($A7="",'Project Overview'!O4="",'Project Overview'!O4="?"),1,0) -> 0 | N7: =IF(OR($A7="",'Project Overview'!P4="", 'Project Overview'!P4="?"),1,0) -> 0 | O7: =SUM(F7:N7) -> 0 | P7: =IF($A7="","",IF($O7=0,"OK","REVER")) -> OK
A8: =""&'Project Overview'!A5 -> 4 | B8: ='Project Overview'!B5 -> Presuntos Lourenço 2 | C8: ='Project Overview'!C5 -> A. Pires Lourenço & Filhos S.A | D8: ='Project Overview'!R5 -> ACTIVE | E8: ='Project Overview'!Y5 -> yes | F8: =IF(AND($A8<>"",$B8=""),1,0) -> 0 | G8: =IF(AND($A8<>"",$C8=""),1,0) -> 0 | H8: =IF(AND($A8<>"",'Project Overview'!D5=""),1,0) -> 0 | I8: =IF(AND($A8<>"",'Project Overview'!F5=""),1,0) -> 0 | J8: =IF(AND($A8<>"",OR('Project Overview'!I5="ESCO",'Project Overview'!I5="EPC",'Project Overview'!I5="ESCO BUYOUT"),'Project Overview'!K5=""),1,0) -> 0 | K8: =IF(AND($A8<>"",'Project Overview'!M5=""),1,0) -> 0 | L8: =IF(AND($A8<>"",'Project Overview'!U5=""),1,0) -> 0 | M8: =IF(OR($A8="",'Project Overview'!O5="",'Project Overview'!O5="?"),1,0) -> 0 | N8: =IF(OR($A8="",'Project Overview'!P5="", 'Project Overview'!P5="?"),1,0) -> 0 | O8: =SUM(F8:N8) -> 0 | P8: =IF($A8="","",IF($O8=0,"OK","REVER")) -> OK | R8: =N8 -> 0
A9: =""&'Project Overview'!A6 -> 4 | B9: ='Project Overview'!B6 -> Pires Lourenço 1 | C9: ='Project Overview'!C6 -> A. Pires Lourenço & Filhos S.A | D9: ='Project Overview'!R6 -> ACTIVE | E9: ='Project Overview'!Y6 -> yes | F9: =IF(OR($A9="",$B9=""),1,0) -> 0 | G9: =IF($C9="",1,0) -> 0 | H9: =IF(AND($A9<>"",'Project Overview'!D6=""),1,0) -> 0 | I9: =IF(AND($A9<>"",'Project Overview'!F6=""),1,0) -> 0 | J9: =IF(AND($A9<>"",OR('Project Overview'!I6="ESCO",'Project Overview'!I6="EPC",'Project Overview'!I6="ESCO BUYOUT"),'Project Overview'!K6=""),1,0) -> 0 | K9: =IF(AND($A9<>"",'Project Overview'!M6=""),1,0) -> 0 | L9: =IF(AND($A9<>"",'Project Overview'!U6=""),1,0) -> 0 | M9: =IF(OR($A9="",'Project Overview'!O6="",'Project Overview'!O6="?"),1,0) -> 0 | N9: =IF(OR($A9="",'Project Overview'!P6="", 'Project Overview'!P6="?"),1,0) -> 0 | O9: =SUM(F9:N9) -> 0 | P9: =IF($A9="","",IF($O9=0,"OK","REVER")) -> OK
A10: =""&'Project Overview'!A7 -> 5 | B10: ='Project Overview'!B7 -> Usinage | C10: ='Project Overview'!C7 -> Usinage - Maquinação e Porta Moldes, Lda | D10: ='Project Overview'!R7 -> ACTIVE | E10: ='Project Overview'!Y7 -> no | F10: =IF(AND($A10<>"",$B10=""),1,0) -> 0 | G10: =IF(AND($A10<>"",$C10=""),1,0) -> 0 | H10: =IF(AND($A10<>"",'Project Overview'!D7=""),1,0) -> 0 | I10: =IF(AND($A10<>"",'Project Overview'!F7=""),1,0) -> 0 | J10: =IF(AND($A10<>"",OR('Project Overview'!I7="ESCO",'Project Overview'!I7="EPC",'Project Overview'!I7="ESCO BUYOUT"),'Project Overview'!K7=""),1,0) -> 0 | K10: =IF(AND($A10<>"",'Project Overview'!M7=""),1,0) -> 0 | L10: =IF(AND($A10<>"",'Project Overview'!U7=""),1,0) -> 0 | M10: =IF(OR($A10="",'Project Overview'!O7="",'Project Overview'!O7="?"),1,0) -> 0 | N10: =IF(OR($A10="",'Project Overview'!P7="", 'Project Overview'!P7="?"),1,0) -> 0 | O10: =SUM(F10:N10) -> 0 | P10: =IF($A10="","",IF($O10=0,"OK","REVER")) -> OK
